Workbook

Sheet З-1. Данные
A1: Имеются следующие данные об уровне розничного товарооборота (млн. руб) | G1: Дано:
C2: объеме промышленного производства (млн. руб) | G2: Y - данные об розничном товарообороте
C3: среднедушевом денежном доходе (тыс. руб) | G3: X - данные об промышленном производстве
A5: в различных населенных пунктах | E5: На основе парной регрессии | U5: Для множественной регрессии
A6: Номер | B6: Розничный товарооброт (y) | C6: Объем промышленного производства (x₁) | D6: Среднедушевой денежный доход (x₂) | E6: x1i * y | F6: x2i * y | G6: x1i² | H6: x2i² | I6: ŷ₁ | J6: ŷ₂ | K6: (ŷ₁-ȳ)² | L6: (ŷ₂-ȳ)² | M6: (yi-ȳ)² | N6: (x₁i-x̄₁)² | O6: (x₂i-x̄₂)² | P6: (yi-ŷ₁)² | Q6: (yi-ŷ2)² | R6: (x₁i-x̄₁)*(x₂i-x̄₂) | S6: (yi-ȳ)*(x₁i-x̄₁) | T6: (yi-ȳ)*(x₂i-x̄₂) | U6: ŷ | V6: SSост | W6: SSфакт
A7: 1 | B7: 118.56 | C7: 247 | D7: 15 | E7: =C7*B7 -> 29284.32 | F7: =D7*B7 -> 1778.4 | G7: =C7^2 -> 61009 | H7: =D7^2 -> 225 | I7: =$B$29+$B$28*C7 -> 129.14594 | J7: ='ДЗ-3'!$B$11+'ДЗ-3'!$B$10*'З-1. Данные'!D7 -> 119.51325 | K7: =(I7-$B$23)^2 -> 1871.3747 | L7: =(J7-$B$23)^2 -> 2797.5721 | M7: =(B7-$B$23)^2 -> 2899.3199 | N7: =(C7-$C$23)^2 -> 4928.04 | O7: =(D7-$D$23)^2 -> 69.444444 | P7: =(B7-I7)^2 -> 112.06223 | Q7: =(B7-J7)^2 -> 0.90869178 | R7: =(C7-$C$23) * (D7-$D$23) -> 585 | S7: =(B7-$B$23)*(C7-$C$23) -> 3779.9424 | T7: =(B7-$B$23)*(D7-$D$23) -> 448.71111 | U7: =$F$29+$F$30*C7+$F$31*D7 -> 112.99019 | V7: =(U7-B7)^2 -> 31.022754 | W7: =(U7-$B$23)^2 -> 3530.1589
A8: 2 | B8: 124.96 | C8: 284 | D8: 18 | E8: =C8*B8 -> 35488.64 | F8: =D8*B8 -> 2249.28 | G8: =C8^2 -> 80656 | H8: =D8^2 -> 324 | I8: =$B$29+$B$28*C8 -> 151.94648 | J8: ='ДЗ-3'!$B$11+'ДЗ-3'!$B$10*'З-1. Данные'!D8 -> 138.5544 | K8: =(I8-$B$23)^2 -> 418.56479 | L8: =(J8-$B$23)^2 -> 1145.8855 | M8: =(B8-$B$23)^2 -> 2251.0597 | N8: =(C8-$C$23)^2 -> 1102.24 | O8: =(D8-$D$23)^2 -> 28.444444 | P8: =(B8-I8)^2 -> 728.26995 | Q8: =(B8-J8)^2 -> 184.80777 | R8: =(C8-$C$23) * (D8-$D$23) -> 177.06667 | S8: =(B8-$B$23)*(C8-$C$23) -> 1575.1851 | T8: =(B8-$B$23)*(D8-$D$23) -> 253.04178 | U8: =$F$29+$F$30*C8+$F$31*D8 -> 137.9316 | V8: =(U8-B8)^2 -> 168.26239 | W8: =(U8-$B$23)^2 -> 1188.4383
A9: 3 | B9: 134.16 | C9: 258 | D9: 18 | E9: =C9*B9 -> 34613.28 | F9: =D9*B9 -> 2414.88 | G9: =C9^2 -> 66564 | H9: =D9^2 -> 324 | I9: =$B$29+$B$28*C9 -> 135.92448 | J9: ='ДЗ-3'!$B$11+'ДЗ-3'!$B$10*'З-1. Данные'!D9 -> 138.5544 | K9: =(I9-$B$23)^2 -> 1330.8526 | L9: =(J9-$B$23)^2 -> 1145.8855 | M9: =(B9-$B$23)^2 -> 1462.7055 | N9: =(C9-$C$23)^2 -> 3504.64 | O9: =(D9-$D$23)^2 -> 28.444444 | P9: =(B9-I9)^2 -> 3.1133949 | Q9: =(B9-J9)^2 -> 19.31077 | R9: =(C9-$C$23) * (D9-$D$23) -> 315.73333 | S9: =(B9-$B$23)*(C9-$C$23) -> 2264.1237 | T9: =(B9-$B$23)*(D9-$D$23) -> 203.97511 | U9: =$F$29+$F$30*C9+$F$31*D9 -> 130.05721 | V9: =(U9-B9)^2 -> 16.832899 | W9: =(U9-$B$23)^2 -> 1793.3637
A10: 4 | B10: 155.04 | C10: 323 | D10: 19 | E10: =C10*B10 -> 50077.92 | F10: =D10*B10 -> 2945.76 | G10: =C10^2 -> 104329 | H10: =D10^2 -> 361 | I10: =$B$29+$B$28*C10 -> 175.97947 | J10: ='ДЗ-3'!$B$11+'ДЗ-3'!$B$10*'З-1. Данные'!D10 -> 144.90145 | K10: =(I10-$B$23)^2 -> 12.774459 | L10: =(J10-$B$23)^2 -> 756.46351 | M10: =(B10-$B$23)^2 -> 301.5548 | N10: =(C10-$C$23)^2 -> 33.64 | O10: =(D10-$D$23)^2 -> 18.777778 | P10: =(B10-I10)^2 -> 438.46144 | Q10: =(B10-J10)^2 -> 102.79016 | R10: =(C10-$C$23) * (D10-$D$23) -> -25.133333 | S10: =(B10-$B$23)*(C10-$C$23) -> -100.71893 | T10: =(B10-$B$23)*(D10-$D$23) -> 75.249778 | U10: =$F$29+$F$30*C10+$F$31*D10 -> 154.3217 | V10: =(U10-B10)^2 -> 0.51595506 | W10: =(U10-$B$23)^2 -> 327.0178
A11: 5 | B11: 161.12 | C11: 304 | D11: 27 | E11: =C11*B11 -> 48980.48 | F11: =D11*B11 -> 4350.24 | G11: =C11^2 -> 92416 | H11: =D11^2 -> 729 | I11: =$B$29+$B$28*C11 -> 164.27109 | J11: ='ДЗ-3'!$B$11+'ДЗ-3'!$B$10*'З-1. Данные'!D11 -> 195.67785 | K11: =(I11-$B$23)^2 -> 66.165925 | L11: =(J11-$B$23)^2 -> 541.60997 | M11: =(B11-$B$23)^2 -> 127.35875 | N11: =(C11-$C$23)^2 -> 174.24 | O11: =(D11-$D$23)^2 -> 13.444444 | P11: =(B11-I11)^2 -> 9.929364 | Q11: =(B11-J11)^2 -> 1194.2449 | R11: =(C11-$C$23) * (D11-$D$23) -> -48.4 | S11: =(B11-$B$23)*(C11-$C$23) -> 148.9664 | T11: =(B11-$B$23)*(D11-$D$23) -> -41.379556 | U11: =$F$29+$F$30*C11+$F$31*D11 -> 185.19545 | V11: =(U11-B11)^2 -> 579.62735 | W11: =(U11-$B$23)^2 -> 163.58711
A12: 6 | B12: 165.13 | C12: 337 | D12: 22 | E12: =C12*B12 -> 55648.81 | F12: =D12*B12 -> 3632.86 | G12: =C12^2 -> 113569 | H12: =D12^2 -> 484 | I12: =$B$29+$B$28*C12 -> 184.6067 | J12: ='ДЗ-3'!$B$11+'ДЗ-3'!$B$10*'З-1. Данные'!D12 -> 163.9426 | K12: =(I12-$B$23)^2 -> 148.87333 | L12: =(J12-$B$23)^2 -> 71.617847 | M12: =(B12-$B$23)^2 -> 52.930475 | N12: =(C12-$C$23)^2 -> 392.04 | O12: =(D12-$D$23)^2 -> 1.7777778 | P12: =(B12-I12)^2 -> 379.34182 | Q12: =(B12-J12)^2 -> 1.4099175 | R12: =(C12-$C$23) * (D12-$D$23) -> -26.4 | S12: =(B12-$B$23)*(C12-$C$23) -> -144.0516 | T12: =(B12-$B$23)*(D12-$D$23) -> 9.7004444 | U12: =$F$29+$F$30*C12+$F$31*D12 -> 172.2973 | V12: =(U12-B12)^2 -> 51.370178 | W12: =(U12-$B$23)^2 -> 0.011671369
A13: 7 | B13: 170 | C13: 340 | D13: 23 | E13: =C13*B13 -> 57800 | F13: =D13*B13 -> 3910 | G13: =C13^2 -> 115600 | H13: =D13^2 -> 529 | I13: =$B$29+$B$28*C13 -> 186.45539 | J13: ='ДЗ-3'!$B$11+'ДЗ-3'!$B$10*'З-1. Данные'!D13 -> 170.28965 | K13: =(I13-$B$23)^2 -> 197.40412 | L13: =(J13-$B$23)^2 -> 4.4761154 | M13: =(B13-$B$23)^2 -> 5.7856284 | N13: =(C13-$C$23)^2 -> 519.84 | O13: =(D13-$D$23)^2 -> 0.11111111 | P13: =(B13-I13)^2 -> 270.7799 | Q13: =(B13-J13)^2 -> 0.083897198 | R13: =(C13-$C$23) * (D13-$D$23) -> -7.6 | S13: =(B13-$B$23)*(C13-$C$23) -> -54.8416 | T13: =(B13-$B$23)*(D13-$D$23) -> 0.80177778 | U13: =$F$29+$F$30*C13+$F$31*D13 -> 177.7844 | V13: =(U13-B13)^2 -> 60.596837 | W13: =(U13-$B$23)^2 -> 28.934326
A14: 8 | B14: 174.42 | C14: 306 | D14: 24 | E14: =C14*B14 -> 53372.52 | F14: =D14*B14 -> 4186.08 | G14: =C14^2 -> 93636 | H14: =D14^2 -> 576 | I14: =$B$29+$B$28*C14 -> 165.50355 | J14: ='ДЗ-3'!$B$11+'ДЗ-3'!$B$10*'З-1. Данные'!D14 -> 176.6367 | K14: =(I14-$B$23)^2 -> 47.634606 | L14: =(J14-$B$23)^2 -> 17.904462 | M14: =(B14-$B$23)^2 -> 4.0588818 | N14: =(C14-$C$23)^2 -> 125.44 | O14: =(D14-$D$23)^2 -> 0.44444444 | P14: =(B14-I14)^2 -> 79.503071 | Q14: =(B14-J14)^2 -> 4.9137577 | R14: =(C14-$C$23) * (D14-$D$23) -> -7.4666667 | S14: =(B14-$B$23)*(C14-$C$23) -> -22.564267 | T14: =(B14-$B$23)*(D14-$D$23) -> 1.3431111 | U14: =$F$29+$F$30*C14+$F$31*D14 -> 172.06563 | V14: =(U14-B14)^2 -> 5.5430541 | W14: =(U14-$B$23)^2 -> 0.11539778
A15: 9 | B15: 175.45 | C15: 290 | D15: 24 | E15: =C15*B15 -> 50880.5 | F15: =D15*B15 -> 4210.8 | G15: =C15^2 -> 84100 | H15: =D15^2 -> 576 | I15: =$B$29+$B$28*C15 -> 155.64386 | J15: ='ДЗ-3'!$B$11+'ДЗ-3'!$B$10*'З-1. Данные'!D15 -> 176.6367 | K15: =(I15-$B$23)^2 -> 280.94696 | L15: =(J15-$B$23)^2 -> 17.904462 | M15: =(B15-$B$23)^2 -> 9.2699951 | N15: =(C15-$C$23)^2 -> 739.84 | O15: =(D15-$D$23)^2 -> 0.44444444 | P15: =(B15-I15)^2 -> 392.28315 | Q15: =(B15-J15)^2 -> 1.4082563 | R15: =(C15-$C$23) * (D15-$D$23) -> -18.133333 | S15: =(B15-$B$23)*(C15-$C$23) -> -82.814933 | T15: =(B15-$B$23)*(D15-$D$23) -> 2.0297778 | U15: =$F$29+$F$30*C15+$F$31*D15 -> 167.21985 | V15: =(U15-B15)^2 -> 67.735339 | W15: =(U15-$B$23)^2 -> 26.889218
A16: 10 | B16: 177.48 | C16: 348 | D16: 27 | E16: =C16*B16 -> 61763.04 | F16: =D16*B16 -> 4791.96 | G16: =C16^2 -> 121104 | H16: =D16^2 -> 729 | I16: =$B$29+$B$28*C16 -> 191.38524 | J16: ='ДЗ-3'!$B$11+'ДЗ-3'!$B$10*'З-1. Данные'!D16 -> 195.67785 | K16: =(I16-$B$23)^2 -> 360.2367 | L16: =(J16-$B$23)^2 -> 541.60997 | M16: =(B16-$B$23)^2 -> 25.752242 | N16: =(C16-$C$23)^2 -> 948.64 | O16: =(D16-$D$23)^2 -> 13.444444 | P16: =(B16-I16)^2 -> 193.35559 | Q16: =(B16-J16)^2 -> 331.16169 | R16: =(C16-$C$23) * (D16-$D$23) -> 112.93333 | S16: =(B16-$B$23)*(C16-$C$23) -> 156.29973 | T16: =(B16-$B$23)*(D16-$D$23) -> 18.607111 | U16: =$F$29+$F$30*C16+$F$31*D16 -> 198.52134 | V16: =(U16-B16)^2 -> 442.73813 | W16: =(U16-$B$23)^2 -> 682.04599
A17: 11 | B17: 190.62 | C17: 353 | D17: 22 | E17: =C17*B17 -> 67288.86 | F17: =D17*B17 -> 4193.64 | G17: =C17^2 -> 124609 | H17: =D17^2 -> 484 | I17: =$B$29+$B$28*C17 -> 194.46639 | J17: ='ДЗ-3'!$B$11+'ДЗ-3'!$B$10*'З-1. Данные'!D17 -> 163.9426 | K17: =(I17-$B$23)^2 -> 486.69018 | L17: =(J17-$B$23)^2 -> 71.617847 | M17: =(B17-$B$23)^2 -> 331.77408 | N17: =(C17-$C$23)^2 -> 1281.64 | O17: =(D17-$D$23)^2 -> 1.7777778 | P17: =(B17-I17)^2 -> 14.794708 | Q17: =(B17-J17)^2 -> 711.68364 | R17: =(C17-$C$23) * (D17-$D$23) -> -47.733333 | S17: =(B17-$B$23)*(C17-$C$23) -> 652.08507 | T17: =(B17-$B$23)*(D17-$D$23) -> -24.286222 | U17: =$F$29+$F$30*C17+$F$31*D17 -> 177.14308 | V17: =(U17-B17)^2 -> 181.62742 | W17: =(U17-$B$23)^2 -> 22.446227
A18: 12 | B18: 197.34 | C18: 299 | D18: 27 | E18: =C18*B18 -> 59004.66 | F18: =D18*B18 -> 5328.18 | G18: =C18^2 -> 89401 | H18: =D18^2 -> 729 | I18: =$B$29+$B$28*C18 -> 161.18994 | J18: ='ДЗ-3'!$B$11+'ДЗ-3'!$B$10*'З-1. Данные'!D18 -> 195.67785 | K18: =(I18-$B$23)^2 -> 125.78513 | L18: =(J18-$B$23)^2 -> 541.60997 | M18: =(B18-$B$23)^2 -> 621.7376 | N18: =(C18-$C$23)^2 -> 331.24 | O18: =(D18-$D$23)^2 -> 13.444444 | P18: =(B18-I18)^2 -> 1306.8271 | Q18: =(B18-J18)^2 -> 2.7627474 | R18: =(C18-$C$23) * (D18-$D$23) -> -66.733333 | S18: =(B18-$B$23)*(C18-$C$23) -> -453.81093 | T18: =(B18-$B$23)*(D18-$D$23) -> 91.427111 | U18: =$F$29+$F$30*C18+$F$31*D18 -> 183.68115 | V18: =(U18-B18)^2 -> 186.56431 | W18: =(U18-$B$23)^2 -> 127.14393
... A21: 15 | B21: 231.28 | C21: 392 | D21: 28 | E21: =C21*B21 -> 90661.76 | F21: =D21*B21 -> 6475.84 | G21: =C21^2 -> 153664 | H21: =D21^2 -> 784 | I21: =$B$29+$B$28*C21 -> 218.49938 | J21: ='ДЗ-3'!$B$11+'ДЗ-3'!$B$10*'З-1. Данные'!D21 -> 202.0249 | K21: =(I21-$B$23)^2 -> 2124.6614 | L21: =(J21-$B$23)^2 -> 877.31862 | M21: =(B21-$B$23)^2 -> 3466.2264 | N21: =(C21-$C$23)^2 -> 5595.04 | O21: =(D21-$D$23)^2 -> 21.777778 | P21: =(B21-I21)^2 -> 163.34418 | Q21: =(B21-J21)^2 -> 855.86098 | R21: =(C21-$C$23) * (D21-$D$23) -> 349.06667 | S21: =(B21-$B$23)*(C21-$C$23) -> 4403.8251 | T21: =(B21-$B$23)*(D21-$D$23) -> 274.74844 | U21: =$F$29+$F$30*C21+$F$31*D21 -> 216.42575 | V21: =(U21-B21)^2 -> 220.64874 | W21: =(U21-$B$23)^2 -> 1937.7971
A22: Сумма | B22: =SUM(B7:B21) -> 2586.08 | C22: =SUM(C7:C21) -> 4758 | D22: =SUM(D7:D21) -> 350 | E22: =SUM(E7:E21) -> 833728.79 | F22: =SUM(F7:F21) -> 61962.48 | G22: =SUM(G7:G21) -> 1531022 | H22: =SUM(H7:H21) -> 8422 | I22: - | J22: - | K22: =SUM(K7:K21) -> 8272.4115 | L22: =SUM(L7:L21) -> 10286.113 | M22: =SUM(M7:M21) -> 13726.233 | N22: =SUM(N7:N21) -> 21784.4 | O22: =SUM(O7:O21) -> 255.33333 | P22: =SUM(P7:P21) -> 5453.8215 | Q22: =SUM(Q7:Q21) -> 3440.1198 | R22: =SUM(R7:R21) -> 1491 | ... W22: =SUM(W7:W21) -> 11485.675
A23: Среднее | B23: =AVERAGE(B7:B21) -> 172.40533 | C23: =AVERAGE(C7:C21) -> 317.2 | D23: =AVERAGE(D7:D21) -> 23.333333 | E23: =AVERAGE(E7:E21) -> 55581.919 | F23: =AVERAGE(F7:F21) -> 4130.832 | G23: =AVERAGE(G7:G21) -> 102068.13 | H23: =AVERAGE(H7:H21) -> 561.46667 | I23: - | J23: - | K23: - | L23: - | M23: - | N23: - | O23: - | P23: -
A26: Для y и x1
A27: Задачи | B27: Парная линейная регрессия | C27: Интерпретация | E27: Множественная линейная регрессия
A28: b̂₁ | B28: =(E23 - B23*C23) / (G23-C23^2) -> 0.61623061 | C28: Направление связи положительное, при изменении объема промышленного производства на 1 млн руб., уровень розничного товарооборота изменится в ту же сторону на ~0.616 млн. руб | D28: - | F28: Коэффициенты
A29: b̂₀ | B29: =B23-B28*C23 -> -23.063015 | C29: Не имеет экономической интерпретации. Так как свободный член меньше нуля, то относительное изменение результата быстрее, чем изменение фактора | D29: - | E29: b̂₀ | F29: -30.494234
A30: Эx | B30: =B28*C23/B23 -> 1.133772 | C30: Если объем промышленного производства изменится на 1% от 317,2 млн руб., то розничный товарооборот изменится на ~1,13% от 172,4 млн руб | D30: - | E30: b̂₁ | F30: 0.30286119
A31: R̂² | B31: =K22/M22 -> 0.60267165 | C31: Означает, что вариация фактора (объема промышленного производства) на ~60% объясняет вариацию уровня розничного товарооборота | D31: - | E31: b̂₂ | F31: 4.5785142
A32: r̂² | B32: =SQRT(B31) -> 0.7763193 | C32: Следовательно, связь тесная | D32: -
A35: Для y и x2
A36: Задачи | B36: Парная линейная регрессия | C36: Интерпретация
A37: b̂₁ | B37: 5.923913 | C37: Направление связи положительное, при изменении среднедушевого денежного дохода на 1 млн руб, уровень розничного товарооборота изменится в ту же сторону на ~5,92 млн руб. | D37: -
A38: b̂₀ | B38: 34.180697 | C38: Не имеет экономической интерпретации. Так как свободный член больше нуля, то относительное изменение результата медленне, чем изменение фактора | D38: -
A39: Эx | B39: 0.80174223 | C39: Если среднедушевой денежный заработок изменится на 1% от 23,3 тыс. руб., то розничный товарооборот изменится на ~0,8% от 172,4 млн руб | D39: -
A40: R̂² | B40: 0.65278999 | C40: Означает, что вариация фактора (среднедушевого денежного заработка) на ~65% объясняет вариацию уровня розничного товарооборота | D40: -
A41: r̂² | B41: 0.8079542 | C41: Следовательно, связь тесная | D41: -

Sheet З-2. Множ. регрессия
A1: Статистические характеристики | B1: Значения
A2: ȳ | B2: ='З-1. Данные'!B23 -> 172.40533
A3: x̄₁ | B3: ='З-1. Данные'!C23 -> 317.2
A4: x̄₂ | B4: ='З-1. Данные'!D23 -> 23.333333
A5: σ²y | B5: ='З-1. Данные'!M22/(B20-1) -> 980.44521
A6: σ²x₁ | B6: ='З-1. Данные'!N22/(B20-1) -> 1556.0286
A7: σ²x₂ | B7: ='З-1. Данные'!O22/(B20-1) -> 18.238095
A8: σy | B8: =SQRT(B5) -> 31.312062
A9: σx₁ | B9: =SQRT(B6) -> 39.446528
A10: σx₂ | B10: =SQRT(B7) -> 4.2706083
A13: ВЫВОД ИТОГОВ
A15: Регрессионная статистика | C15: Выводы
A16: Множественный R | B16: 0.91475032 | C16: Характеризует очень тесную положительную связь между зависимой переменной уровня розничного товарообората и независимых факторов
A17: R-квадрат | B17: 0.83676815 | C17: Показывает, что вариация независимых факторов модели регрессии объяняют ~83% вариации уровня розничного товарооборота
A18: Нормированный R-квадрат | B18: 0.80956285 | C18: Скорревтированный коэф. Детерминации, будет важен для выбора лучшей модели, если мы сравниваем модели с разным числом объясняющих переменных
A19: Стандартная ошибка | B19: 13.664304 | C19: Средняя ошибка прогноза, то что мы минимизируем
A20: Наблюдения | B20: 15
A22: Дисперсионный анализ
B23: df | C23: SS | D23: MS | E23: F | F23: Значимость F | G23: Выводы
A24: Регрессия | B24: 2 | C24: 11485.675 | D24: 5742.8373 | E24: 30.757533 | F24: 1.8916002e-05 | G24: Значимость p-value (то есть F) крайне мала 0,0000189 по сравнению с уровнем значимости 0.05. Следовательно, отвергаем гипотезу H0 о незначимости коэф. Регрессии на уровне значимости 0.05. Они являются статистически значимыми
A25: Остаток | B25: 12 | C25: 2240.5584 | D25: 186.7132
A26: Итого | B26: 14 | C26: 13726.233
B28: Коэффициенты | C28: Стандартная ошибка | D28: t-статистика | E28: P-Значение | F28: Нижние 95% | G28: Верхние 95% | H28: Нижние 95,0% | I28: Верхние 95,0% | J28: Выводы
A29: Y-пересечение | B29: -30.494234 | C29: 29.631581 | D29: -1.0291126 | E29: 0.32372389 | F29: -95.055904 | G29: 34.067435 | H29: -95.055904 | I29: 34.067435 | J29: p-value = 0.32 > 0.05. Следовательно, свободные член статистически незначим на уровне значимости 0.05
A30: Объем промышленного производства (X) | B30: 0.30286119 | C30: 0.11948679 | D30: 2.5346835 | E30: 0.026193005 | F30: 0.042521841 | G30: 0.56320054 | H30: 0.042521841 | I30: 0.56320054 | J30: p-value = 0.03 < 0.05. Следовательно, коэф. Регрессии b̂₁ статистически значим
A31: Среднедушевой денежный доход | B31: 4.5785142 | C31: 1.1036692 | D31: 4.1484479 | E31: 0.0013503188 | F31: 2.1738256 | G31: 6.9832029 | H31: 2.1738256 | I31: 6.9832029 | J31: p-value = 0.0014 << 0.05. Следовательно, коэф регрессии b̂₂ статистически значим. Причем область риска настолько мала, что говорит о сильном влиянии на Y
A35: ВЫВОД ОСТАТКА
A37: Наблюдение | B37: Предсказанное Розничный товарооброт (Y) | C37: Остатки | D37: Стандартные остатки
A38: 1 | B38: 112.99019 | C38: 5.5698074 | D38: 0.44027707 | F38: =C38^2 -> 31.022754
A39: 2 | B39: 137.9316 | C39: -12.971599 | D39: -1.0253672 | F39: =C39^2 -> 168.26239
A40: 3 | B40: 130.05721 | C40: 4.1027916 | D40: 0.32431374 | F40: =C40^2 -> 16.832899
A41: 4 | B41: 154.3217 | C41: 0.71830012 | D41: 0.056779535 | F41: =C41^2 -> 0.51595506
A42: 5 | B42: 185.19545 | C42: -24.075451 | D42: -1.9030944 | F42: =C42^2 -> 579.62735
A43: 6 | B43: 172.2973 | C43: -7.1672992 | D43: -0.56655415 | F43: =C43^2 -> 51.370178
A44: 7 | B44: 177.7844 | C44: -7.784397 | D44: -0.61533393 | F44: =C44^2 -> 60.596837
A45: 8 | B45: 172.06563 | C45: 2.3543692 | D45: 0.18610603 | F45: =C45^2 -> 5.5430541
A46: 9 | B46: 167.21985 | C46: 8.2301482 | D46: 0.65056927 | F46: =C46^2 -> 67.735339
A47: 10 | B47: 198.52134 | C47: -21.041343 | D47: -1.663257 | F47: =C47^2 -> 442.73813
A48: 11 | B48: 177.14308 | C48: 13.476922 | D48: 1.0653115 | F48: =C48^2 -> 181.62742
A49: 12 | B49: 183.68115 | C49: 13.658855 | D49: 1.0796927 | F49: =C49^2 -> 186.56431
...

Sheet З-3. Значимость параметров
A1: Входные данные | B1: Значения | D1: Задание
A2: n | B2: ='З-2. Множ. регрессия'!B20 -> 15 | D2: Оцените значимость коэффициента регрессии двумя способами с помощью LO Calk. Сделайте выводы.
A3: α | B3: 0.05 | D3: Оцените значимость свободного члена двумя способами с помощью LO Calk Сделайте выводы.
A5: - | B5: - | C5: - | D5: Через p-value (сравнение tфакт и tкрит) | G5: Через доверительный интервал | I5: Интерпретация
A6: Требуется оценить | B6: Значения | C6: se(*) | D6: tфакт. | E6: tкрит. | F6: p-value (%) | G6: Левая граница | H6: Правая граница | I6: 1 способ | J6: 2 способ
A7: b̂₁ | B7: ='З-1. Данные'!B28 -> 0.61623061 | C7: =SQRT('З-1. Данные'!P22/((B2-2) * 'З-1. Данные'!N22)) -> 0.13877332 | D7: =ABS(B7/C7) -> 4.4405553 | E7: =_xlfn.T.INV.2T($B$3, $B$2-2) -> 2.1603687 | F7: =_xlfn.T.DIST.2T(D7,$B$2-2) -> 0.00066607367 | G7: =B7-E7*C7 -> 0.31642907 | H7: =B7+E7*C7 -> 0.91603214 | I7: p-value < 5%, следовательно, отвергаем H0 о незначимости коэф регрессии. Иными словами, нет оснований отвергать гипотезу о значимости коэф регрессии на уровне значимости 0.05 (tфакт. > tкрит. Следовательно, отвергаем гипотезу H0 о незначимости коэф. регрессии) | J7: Истинное значение коэф. Регресси лежит в интервале [0,32; 0,92] с вероятностью ошибки 0.05
A8: b̂₀ | B8: ='З-1. Данные'!B29 -> -23.063015 | C8: =C7*SQRT('З-1. Данные'!G22/B2) -> 44.335444 | D8: =ABS(B8/C8) -> 0.52019361 | E8: =_xlfn.T.INV.2T($B$3, $B$2-2) -> 2.1603687 | F8: =_xlfn.T.DIST.2T(D8,$B$2-2) -> 0.61167325 | G8: =B8-E8*C8 -> -118.84392 | H8: =B8+E8*C8 -> 72.71789 | I8: p-value > 5%, следовательно, не отвергаем гипотезу H0 о незначимости свободного члена на уровне значимости 0,05 (tфакт. < tкрит. Следовательно, не отвергаем гипотезу H0 о незначимости свободного члена) | J8: Истинное значение коэф. Регресси лежит в интервале [-118,8; 72,7] с вероятностью ошибки 0.05. Как видно, интервал достаточно широкий

Sheet ДЗ-3
A1: Входные данные | B1: Значения | E1: Задание
A2: n | B2: 15 | E2: Найдите параметры уравнения линейной регрессии розничного товарооборота от среднедушевого денежного дохода. Сделайте выводы.
A3: (x2i*y).ср. | B3: ='З-1. Данные'!F23 -> 4130.832 | E3: Найдите коэффициент корреляции и детерминации. Сделайте выводы.
A4: ȳ | B4: ='З-1. Данные'!B23 -> 172.40533
A5: x̄2i | B5: ='З-1. Данные'!D23 -> 23.333333
A6: σx2 | B6: ='З-1. Данные'!O22/('ДЗ-3'!B2) -> 17.022222
A9: Задачи | B9: Парная линейная регрессия | C9: Интерпретация
A10: b̂₁ | B10: =(B3 - B5 * B4) / B6 -> 6.3470496 | C10: Направление связи положительное, при изменении среднедушевого денежного дохода на 1 млн руб, уровень розничного товарооборота изменится в ту же сторону на ~5,92 млн руб. | D10: -
A11: b̂₀ | B11: =B4-B10*B5 -> 24.307509 | C11: Не имеет экономической интерпретации. Так как свободный член больше нуля, то относительное изменение результата медленне, чем изменение фактора | D11: -
A12: Эx | B12: =B10*B5/B4 -> 0.85900953 | C12: Если среднедушевой денежный заработок изменится на 1% от 23,3 тыс. руб., то розничный товарооборот изменится на ~0,8% от 172,4 млн руб | D12: -
A13: R̂² | B13: ='З-1. Данные'!L22/'З-1. Данные'!M22 -> 0.74937627 | C13: Означает, что вариация фактора (среднедушевого денежного заработка) на ~65% объясняет вариацию уровня розничного товарооборота | D13: -
A14: r̂² | B14: =SQRT(B13) -> 0.86566522 | C14: Следовательно, связь тесная | D14: -

Sheet ДЗ-4
A1: Входные данные | B1: Значение | E1: Задание
A2: n | B2: 15 | E2: По данным домашнего задания 1 оцените значимость коэффициента регрессии и уравнения регрессии в целом. Сделайте выводы.
A3: α | B3: 0.05 | E3: H0 | F3: Уравнение регрессии незначимо (все коэф регрессии равны нулю)
A4: R̂² | B4: ='З-1. Данные'!B31 -> 0.60267165 | E4: H1 | F4: Уравнение регрессии значимо (хотя бы один коэф регрессии не равен нулю)
A8: Таблица дисперсионного анализа (для парной регрессии из задания 1)
A9: Источник информации | B9: df | C9: SS | D9: MS | E9: Fфакт. | I9: Fтабл. | J9: Интерпретация
A10: - | B10: - | C10: - | D10: - | E10: Msфакт/Msостат. | F10: Через R̂² | G10: t²b̂₂ | H10: Excel | I10: - | J10: Так как Fфакт. > Fкрит. , то отвергаем гипотезу H0 о незначимости уравнения регрессии на уровне значимости 0.05
A11: Регрессия | B11: 1 | C11: ='З-1. Данные'!K22 -> 8272.4115 | D11: =C11/B11 -> 8272.4115 | E11: =D11/D12 -> 19.718531 | F11: =(B4 / (1-B4)) * (B12 / B11) -> 19.718531 | G11: ='З-3. Значимость параметров'!D7^2 -> 19.718531 | H11: =E30 -> 19.718531 | I11: =_xlfn.F.INV.RT(B3,B11,B12) -> 4.6671927
A12: Случайное отклонение | B12: =B2-B11-1 -> 13 | C12: ='З-1. Данные'!P22 -> 5453.8215 | D12: =C12/B12 -> 419.52473
A13: Общая | B13: =B2-1 -> 14 | C13: ='З-1. Данные'!M22 -> 13726.233
A19: ВЫВОД ИТОГОВ
A21: Регрессионная статистика
A22: Множественный R | B22: 0.7763193
A23: R-квадрат | B23: 0.60267165
A24: Нормированный R-квадрат | B24: 0.57210793
A25: Стандартная ошибка | B25: 20.482303
A26: Наблюдения | B26: 15
A28: Дисперсионный анализ
B29: df | C29: SS | D29: MS | E29: F | F29: Значимость F
A30: Регрессия | B30: 1 | C30: 8272.4115 | D30: 8272.4115 | E30: 19.718531 | F30: 0.00066607367
A31: Остаток | B31: 13 | C31: 5453.8215 | D31: 419.52473
A32: Итого | B32: 14 | C32: 13726.233
B34: Коэффициенты | C34: Стандартная ошибка | D34: t-статистика | E34: P-Значение | F34: Нижние 95% | G34: Верхние 95% | H34: Нижние 95,0% | I34: Верхние 95,0%
A35: Y-пересечение | B35: -23.063015 | C35: 44.335444 | D35: -0.52019361 | E35: 0.61167325 | F35: -118.84392 | G35: 72.71789 | H35: -118.84392 | I35: 72.71789
A36: Объем промышленного производства (x₁) | B36: 0.61623061 | C36: 0.13877332 | D36: 4.4405553 | E36: 0.00066607367 | F36: 0.31642907 | G36: 0.91603214 | H36: 0.31642907 | I36: 0.91603214

Sheet З-5. Прогноз
A1: Входные данные | B1: Значения | E1: Задание
A2: n | B2: 15 | E2: Найти точечный прогноз и нижнюю и верхнюю границу интервального прогноза при x1,пр = 300
A3: α | B3: 0.05
A4: b̂₁ | B4: ='З-1. Данные'!B28 -> 0.61623061
A5: b̂₀ | B5: ='З-1. Данные'!B29 -> -23.063015
A6: x1,пр | B6: 300
A7: x̄₁ | B7: ='З-1. Данные'!C23 -> 317.2
A8: tкрит. | B8: =_xlfn.T.INV.2T($B$3, $B$2-2) -> 2.1603687
A10: Задачи | B10: Значения
A11: ŷпр | B11: =B5+B4*B6 -> 161.80617
A12: se(ŷпр) | B12: =SQRT('З-1. Данные'!K22 / (B2-2) * (1 + 1/B2 + (B6-B7)^2/('З-1. Данные'!N22))) -> 26.218385
A13: Левая граница | B13: =B11-B8*B12 -> 105.16479
A14: Правая граница | B14: =B11+B8*B12 -> 218.44754
A15: Интерпретация | B15: Если ожидается объем промышленного производства в 300 млн. рублей, то уровень розничного товараоборота в среднем составит 161,8 млн. руб. и с вероятностью 0.95 истинное значение уровня розничного товарооборота будет находится в интервале от 105,16 до 218,4

Sheet Лист5

Sheet З-6. Анализ нелинейных функций
B3: Данные | G3: Гипербола | Q3: Парабола | AA3: Степенная (наиболее точная модель) | AK3: Показательная | AU3: Полулогарифмическая
B4: Номер | C4: Розничный товарооброт (y) | D4: Объем промышленного производства (x₁) | E4: Среднедушевойденежный доход (x₂) | G4: Розничный товарооброт (y) | H4: z₂ = 1/x₂ | I4: ŷ | J4: MAPE | Q4: Розничный товарооброт (y) | R4: z₁ = x₂ | S4: z₂ = x₂² | T4: ŷ | U4: MAPE | AA4: Y = ln(y) | AB4: X = ln(x₂) | AC4: ln(ŷ) | AD4: ŷ | AE4: MAPE | AK4: Y = ln(y) | AL4: x₂ | AM4: ln(ŷ) | AN4: ŷ | AO4: MAPE | AU4: y | AV4: z₂=ln(x₂) | AW4: ŷ | AX4: MAPE
B5: 1 | C5: 118.56 | D5: 247 | E5: 15 | G5: =$C5 -> 118.56 | H5: =1/$E5 -> 0.066666667 | I5: =H48 -> 108.24311 | J5: =1/$B$19*SUM(ABS(($C5 - I5)/$C5)) -> 0.0058012187 | Q5: =$C5 -> 118.56 | R5: =$E5 -> 15 | S5: =R5^2 -> 225 | T5: =R48 -> 116.89588 | U5: =1/$B$19*SUM(ABS(($C5 - T5)/$C5)) -> 0.00093573727 | AA5: =LN($C5) -> 4.7754192 | AB5: =LN($E5) -> 2.7080502 | AC5: =AB48 -> 4.7715302 | AD5: =EXP(AC5) -> 118.09982 | AE5: =1/$B$19*SUM(ABS(($C5 - AD5)/$C5)) -> 0.00025876181 | AK5: =LN($C5) -> 4.7754192 | AL5: =$E5 -> 15 | AM5: =AL48 -> 4.8094965 | AN5: =EXP(AM5) -> 122.66984 | AO5: =1/$B$19*SUM(ABS(($C5 - AN5)/$C5)) -> 0.0023109755 | AU5: =$C5 -> 118.56 | AV5: =LN($E5) -> 2.7080502 | AW5: =AV48 -> 113.76015 | AX5: =1/$B$19*SUM(ABS(($C5 - AW5)/$C5)) -> 0.0026989691
B6: 2 | C6: 124.96 | D6: 284 | E6: 18 | G6: =$C6 -> 124.96 | H6: =1/$E6 -> 0.055555556 | I6: =H49 -> 140.29704 | J6: =1/$B$19*SUM(ABS(($C6 - I6)/$C6)) -> 0.0081823742 | Q6: =$C6 -> 124.96 | R6: =$E6 -> 18 | S6: =R6^2 -> 324 | T6: =R49 -> 138.50536 | U6: =1/$B$19*SUM(ABS(($C6 - T6)/$C6)) -> 0.007226505 | AA6: =LN($C6) -> 4.8279937 | AB6: =LN($E6) -> 2.8903718 | AC6: =AB49 -> 4.9270212 | AD6: =EXP(AC6) -> 137.96793 | AE6: =1/$B$19*SUM(ABS(($C6 - AD6)/$C6)) -> 0.0069397813 | AK6: =LN($C6) -> 4.8279937 | AL6: =$E6 -> 18 | AM6: =AL49 -> 4.9262167 | AN6: =EXP(AM6) -> 137.85697 | AO6: =1/$B$19*SUM(ABS(($C6 - AN6)/$C6)) -> 0.0068805865 | AU6: =$C6 -> 124.96 | AV6: =LN($E6) -> 2.8903718 | AW6: =AV49 -> 138.93706 | AX6: =1/$B$19*SUM(ABS(($C6 - AW6)/$C6)) -> 0.0074568179
B7: 3 | C7: 134.16 | D7: 258 | E7: 18 | G7: =$C7 -> 134.16 | H7: =1/$E7 -> 0.055555556 | I7: =H50 -> 140.29704 | J7: =1/$B$19*SUM(ABS(($C7 - I7)/$C7)) -> 0.0030496135 | Q7: =$C7 -> 134.16 | R7: =$E7 -> 18 | S7: =R7^2 -> 324 | T7: =R50 -> 138.50536 | U7: =1/$B$19*SUM(ABS(($C7 - T7)/$C7)) -> 0.0021592929 | AA7: =LN($C7) -> 4.8990331 | AB7: =LN($E7) -> 2.8903718 | AC7: =AB50 -> 4.9270212 | AD7: =EXP(AC7) -> 137.96793 | AE7: =1/$B$19*SUM(ABS(($C7 - AD7)/$C7)) -> 0.0018922312 | AK7: =LN($C7) -> 4.8990331 | AL7: =$E7 -> 18 | AM7: =AL50 -> 4.9262167 | AN7: =EXP(AM7) -> 137.85697 | AO7: =1/$B$19*SUM(ABS(($C7 - AN7)/$C7)) -> 0.0018370957 | AU7: =$C7 -> 134.16 | AV7: =LN($E7) -> 2.8903718 | AW7: =AV50 -> 138.93706 | AX7: =1/$B$19*SUM(ABS(($C7 - AW7)/$C7)) -> 0.0023738121
B8: 4 | C8: 155.04 | D8: 323 | E8: 19 | G8: =$C8 -> 155.04 | H8: =1/$E8 -> 0.052631579 | I8: =H51 -> 148.73229 | J8: =1/$B$19*SUM(ABS(($C8 - I8)/$C8)) -> 0.0027122949 | Q8: =$C8 -> 155.04 | R8: =$E8 -> 19 | S8: =R8^2 -> 361 | T8: =R51 -> 145.41458 | U8: =1/$B$19*SUM(ABS(($C8 - T8)/$C8)) -> 0.0041388975 | AA8: =LN($C8) -> 5.0436831 | AB8: =LN($E8) -> 2.944439 | AC8: =AB51 -> 4.9731319 | AD8: =EXP(AC8) -> 144.47867 | AE8: =1/$B$19*SUM(ABS(($C8 - AD8)/$C8)) -> 0.004541334 | AK8: =LN($C8) -> 5.0436831 | AL8: =$E8 -> 19 | AM8: =AL51 -> 4.9651234 | AN8: =EXP(AM8) -> 143.32624 | AO8: =1/$B$19*SUM(ABS(($C8 - AN8)/$C8)) -> 0.0050368759 | AU8: =$C8 -> 155.04 | AV8: =LN($E8) -> 2.944439 | AW8: =AV51 -> 146.40324 | AX8: =1/$B$19*SUM(ABS(($C8 - AW8)/$C8)) -> 0.0037137778
B9: 5 | C9: 161.12 | D9: 304 | E9: 27 | G9: =$C9 -> 161.12 | H9: =1/$E9 -> 0.037037037 | I9: =H52 -> 193.72026 | J9: =1/$B$19*SUM(ABS(($C9 - I9)/$C9)) -> 0.013489018 | Q9: =$C9 -> 161.12 | R9: =$E9 -> 27 | S9: =R9^2 -> 729 | T9: =R52 -> 195.39742 | U9: =1/$B$19*SUM(ABS(($C9 - T9)/$C9)) -> 0.014182976 | AA9: =LN($C9) -> 5.0821494 | AB9: =LN($E9) -> 3.2958369 | AC9: =AB52 -> 5.272818 | AD9: =EXP(AC9) -> 194.96459 | AE9: =1/$B$19*SUM(ABS(($C9 - AD9)/$C9)) -> 0.014003887 | AK9: =LN($C9) -> 5.0821494 | AL9: =$E9 -> 27 | AM9: =AL52 -> 5.2763773 | AN9: =EXP(AM9) -> 195.65977 | AO9: =1/$B$19*SUM(ABS(($C9 - AN9)/$C9)) -> 0.014291532 | AU9: =$C9 -> 161.12 | AV9: =LN($E9) -> 3.2958369 | AW9: =AV52 -> 194.92801 | AX9: =1/$B$19*SUM(ABS(($C9 - AW9)/$C9)) -> 0.013988749
B10: 6 | C10: 165.13 | D10: 337 | E10: 22 | G10: =$C10 -> 165.13 | H10: =1/$E10 -> 0.045454545 | I10: =H53 -> 169.43698 | J10: =1/$B$19*SUM(ABS(($C10 - I10)/$C10)) -> 0.0017388232 | Q10: =$C10 -> 165.13 | R10: =$E10 -> 22 | S10: =R10^2 -> 484 | T10: =R53 -> 165.26042 | U10: =1/$B$19*SUM(ABS(($C10 - T10)/$C10)) -> 5.2652492e-05 | AA10: =LN($C10) -> 5.106733 | AB10: =LN($E10) -> 3.0910425 | AC10: =AB53 -> 5.0981612 | AD10: =EXP(AC10) -> 163.72058 | AE10: =1/$B$19*SUM(ABS(($C10 - AD10)/$C10)) -> 0.00056901603 | AK10: =LN($C10) -> 5.106733 | AL10: =$E10 -> 22 | AM10: =AL53 -> 5.0818436 | AN10: =EXP(AM10) -> 161.07074 | AO10: =1/$B$19*SUM(ABS(($C10 - AN10)/$C10)) -> 0.0016388143 | AU10: =$C10 -> 165.13 | AV10: =LN($E10) -> 3.0910425 | AW10: =AV53 -> 166.64781 | AX10: =1/$B$19*SUM(ABS(($C10 - AW10)/$C10)) -> 0.0006127739
B11: 7 | C11: 170 | D11: 340 | E11: 23 | G11: =$C11 -> 170 | H11: =1/$E11 -> 0.043478261 | I11: =H54 -> 175.13827 | J11: =1/$B$19*SUM(ABS(($C11 - I11)/$C11)) -> 0.0020150079 | Q11: =$C11 -> 170 | R11: =$E11 -> 23 | S11: =R11^2 -> 529 | T11: =R54 -> 171.58176 | U11: =1/$B$19*SUM(ABS(($C11 - T11)/$C11)) -> 0.00062029689 | AA11: =LN($C11) -> 5.1357984 | AB11: =LN($E11) -> 3.1354942 | AC11: =AB54 -> 5.1360714 | AD11: =EXP(AC11) -> 170.04641 | AE11: =1/$B$19*SUM(ABS(($C11 - AD11)/$C11)) -> 1.8199668e-05 | AK11: =LN($C11) -> 5.1357984 | AL11: =$E11 -> 23 | AM11: =AL54 -> 5.1207504 | AN11: =EXP(AM11) -> 167.46098 | AO11: =1/$B$19*SUM(ABS(($C11 - AN11)/$C11)) -> 0.00099569385 | AU11: =$C11 -> 170 | AV11: =LN($E11) -> 3.1354942 | AW11: =AV54 -> 172.78618 | AX11: =1/$B$19*SUM(ABS(($C11 - AW11)/$C11)) -> 0.0010926212
B12: 8 | C12: 174.42 | D12: 306 | E12: 24 | G12: =$C12 -> 174.42 | H12: =1/$E12 -> 0.041666667 | I12: =H55 -> 180.36445 | J12: =1/$B$19*SUM(ABS(($C12 - I12)/$C12)) -> 0.0022720843 | Q12: =$C12 -> 174.42 | R12: =$E12 -> 24 | S12: =R12^2 -> 576 | T12: =R55 -> 177.75613 | U12: =1/$B$19*SUM(ABS(($C12 - T12)/$C12)) -> 0.0012751315 | AA12: =LN($C12) -> 5.1614662 | AB12: =LN($E12) -> 3.1780538 | AC12: =AB55 -> 5.1723679 | AD12: =EXP(AC12) -> 176.33188 | AE12: =1/$B$19*SUM(ABS(($C12 - AD12)/$C12)) -> 0.0007307586 | AK12: =LN($C12) -> 5.1614662 | AL12: =$E12 -> 24 | AM12: =AL55 -> 5.1596571 | AN12: =EXP(AM12) -> 174.10475 | AO12: =1/$B$19*SUM(ABS(($C12 - AN12)/$C12)) -> 0.00012049616 | AU12: =$C12 -> 174.42 | AV12: =LN($E12) -> 3.1780538 | AW12: =AV55 -> 178.66327 | AX12: =1/$B$19*SUM(ABS(($C12 - AW12)/$C12)) -> 0.001621859
B13: 9 | C13: 175.45 | D13: 290 | E13: 24 | G13: =$C13 -> 175.45 | H13: =1/$E13 -> 0.041666667 | I13: =H56 -> 180.36445 | J13: =1/$B$19*SUM(ABS(($C13 - I13)/$C13)) -> 0.0018673712 | Q13: =$C13 -> 175.45 | R13: =$E13 -> 24 | S13: =R13^2 -> 576 | T13: =R56 -> 177.75613 | U13: =1/$B$19*SUM(ABS(($C13 - T13)/$C13)) -> 0.00087627118 | AA13: =LN($C13) -> 5.1673541 | AB13: =LN($E13) -> 3.1780538 | AC13: =AB56 -> 5.1723679 | AD13: =EXP(AC13) -> 176.33188 | AE13: =1/$B$19*SUM(ABS(($C13 - AD13)/$C13)) -> 0.00033509404 | AK13: =LN($C13) -> 5.1673541 | AL13: =$E13 -> 24 | AM13: =AL56 -> 5.1596571 | AN13: =EXP(AM13) -> 174.10475 | AO13: =1/$B$19*SUM(ABS(($C13 - AN13)/$C13)) -> 0.00051116333 | AU13: =$C13 -> 175.45 | AV13: =LN($E13) -> 3.1780538 | AW13: =AV56 -> 178.66327 | AX13: =1/$B$19*SUM(ABS(($C13 - AW13)/$C13)) -> 0.0012209631
B14: 10 | C14: 177.48 | D14: 348 | E14: 27 | G14: =$C14 -> 177.48 | H14: =1/$E14 -> 0.037037037 | I14: =H57 -> 193.72026 | J14: =1/$B$19*SUM(ABS(($C14 - I14)/$C14)) -> 0.0061003148 | Q14: =$C14 -> 177.48 | R14: =$E14 -> 27 | S14: =R14^2 -> 729 | T14: =R57 -> 195.39742 | U14: =1/$B$19*SUM(ABS(($C14 - T14)/$C14)) -> 0.0067303043 | AA14: =LN($C14) -> 5.1788579 | AB14: =LN($E14) -> 3.2958369 | AC14: =AB57 -> 5.272818 | AD14: =EXP(AC14) -> 194.96459 | AE14: =1/$B$19*SUM(ABS(($C14 - AD14)/$C14)) -> 0.0065677233 | AK14: =LN($C14) -> 5.1788579 | AL14: =$E14 -> 27 | AM14: =AL57 -> 5.2763773 | AN14: =EXP(AM14) -> 195.65977 | AO14: =1/$B$19*SUM(ABS(($C14 - AN14)/$C14)) -> 0.0068288537 | AU14: =$C14 -> 177.48 | AV14: =LN($E14) -> 3.2958369 | AW14: =AV57 -> 194.92801 | AX14: =1/$B$19*SUM(ABS(($C14 - AW14)/$C14)) -> 0.0065539809
B15: 11 | C15: 190.62 | D15: 353 | E15: 22 | G15: =$C15 -> 190.62 | H15: =1/$E15 -> 0.045454545 | I15: =H58 -> 169.43698 | J15: =1/$B$19*SUM(ABS(($C15 - I15)/$C15)) -> 0.0074084642 | Q15: =$C15 -> 190.62 | R15: =$E15 -> 22 | S15: =R15^2 -> 484 | T15: =R58 -> 165.26042 | U15: =1/$B$19*SUM(ABS(($C15 - T15)/$C15)) -> 0.0088691576 | AA15: =LN($C15) -> 5.2502819 | AB15: =LN($E15) -> 3.0910425 | AC15: =AB58 -> 5.0981612 | AD15: =EXP(AC15) -> 163.72058 | AE15: =1/$B$19*SUM(ABS(($C15 - AD15)/$C15)) -> 0.0094076957 | AK15: =LN($C15) -> 5.2502819 | AL15: =$E15 -> 22 | AM15: =AL58 -> 5.0818436 | AN15: =EXP(AM15) -> 161.07074 | AO15: =1/$B$19*SUM(ABS(($C15 - AN15)/$C15)) -> 0.010334439 | AU15: =$C15 -> 190.62 | AV15: =LN($E15) -> 3.0910425 | AW15: =AV58 -> 166.64781 | AX15: =1/$B$19*SUM(ABS(($C15 - AW15)/$C15)) -> 0.0083839365
B16: 12 | C16: 197.34 | D16: 299 | E16: 27 | G16: =$C16 -> 197.34 | H16: =1/$E16 -> 0.037037037 | I16: =H59 -> 193.72026 | J16: =1/$B$19*SUM(ABS(($C16 - I16)/$C16)) -> 0.0012228444 | Q16: =$C16 -> 197.34 | R16: =$E16 -> 27 | S16: =R16^2 -> 729 | T16: =R59 -> 195.39742 | U16: =1/$B$19*SUM(ABS(($C16 - T16)/$C16)) -> 0.00065625613 | AA16: =LN($C16) -> 5.2849281 | AB16: =LN($E16) -> 3.2958369 | AC16: =AB59 -> 5.272818 | AD16: =EXP(AC16) -> 194.96459 | AE16: =1/$B$19*SUM(ABS(($C16 - AD16)/$C16)) -> 0.00080247526 | AK16: =LN($C16) -> 5.2849281 | AL16: =$E16 -> 27 | AM16: =AL59 -> 5.2763773 | AN16: =EXP(AM16) -> 195.65977 | AO16: =1/$B$19*SUM(ABS(($C16 - AN16)/$C16)) -> 0.00056762467 | AU16: =$C16 -> 197.34 | AV16: =LN($E16) -> 3.2958369 | AW16: =AV59 -> 194.92801 | AX16: =1/$B$19*SUM(ABS(($C16 - AW16)/$C16)) -> 0.00081483462
... B19: 15 | C19: 231.28 | D19: 392 | E19: 28 | G19: =$C19 -> 231.28 | H19: =1/$E19 -> 0.035714286 | I19: =H62 -> 197.5362 | J19: =1/$B$19*SUM(ABS(($C19 - I19)/$C19)) -> 0.0097266799 | Q19: =$C19 -> 231.28 | R19: =$E19 -> 28 | S19: =R19^2 -> 784 | T19: =R62 -> 200.98391 | U19: =1/$B$19*SUM(ABS(($C19 - T19)/$C19)) -> 0.0087328761 | AA19: =LN($C19) -> 5.4436291 | AB19: =LN($E19) -> 3.3322045 | AC19: =AB62 -> 5.3038337 | AD19: =EXP(AC19) -> 201.10632 | AE19: =1/$B$19*SUM(ABS(($C19 - AD19)/$C19)) -> 0.0086975894 | AK19: =LN($C19) -> 5.4436291 | AL19: =$E19 -> 28 | AM19: =AL62 -> 5.315284 | AN19: =EXP(AM19) -> 203.42228 | AO19: =1/$B$19*SUM(ABS(($C19 - AN19)/$C19)) -> 0.0080300114 | AU19: =$C19 -> 231.28 | AV19: =LN($E19) -> 3.3322045 | AW19: =AV62 -> 199.95004 | AX19: =1/$B$19*SUM(ABS(($C19 - AW19)/$C19)) -> 0.0090308888
B20: Сумма | C20: =SUM(C5:C19) -> 2586.08 | D20: =SUM(D5:D19) -> 4758 | E20: =SUM(E5:E19) -> 350 | G20: =SUM(G5:G19) -> 2586.08 | H20: =SUM(H5:H19) -> 0.66638401 | I20: =SUM(I5:I19) -> 2586.08 | J20: =SUM(J5:J19) -> 0.070591413 | Q20: =SUM(Q5:Q19) -> 2586.08 | R20: =SUM(R5:R19) -> 350 | S20: =SUM(S5:S19) -> 8422 | T20: =SUM(T5:T19) -> 2586.08 | U20: =SUM(U5:U19) -> 0.059221882 | AA20: =SUM(AA5:AA19) -> 77.005789 | AB20: =SUM(AB5:AB19) -> 46.991044 | AC20: =SUM(AC5:AC19) -> 77.005789 | AD20: =SUM(AD5:AD19) -> 2576.8784 | AE20: =SUM(AE5:AE19) -> 0.057450547 | AK20: =SUM(AK5:AK19) -> 77.005789 | AL20: =SUM(AL5:AL19) -> 350 | AM20: =SUM(AM5:AM19) -> 77.005789 | AN20: =SUM(AN5:AN19) -> 2576.7681 | AO20: =SUM(AO5:AO19) -> 0.060658939 | AU20: =SUM(AU5:AU19) -> 2586.08 | AV20: =SUM(AV5:AV19) -> 46.991044 | AW20: =SUM(AW5:AW19) -> 2586.08 | AX20: =SUM(AX5:AX19) -> 0.063001154
B21: Среднее | C21: =AVERAGE(C5:C19) -> 172.40533 | D21: =AVERAGE(D5:D19) -> 317.2 | E21: =AVERAGE(E5:E19) -> 23.333333 | G21: =AVERAGE(G5:G19) -> 172.40533 | H21: =AVERAGE(H5:H19) -> 0.044425601 | I21: =AVERAGE(I5:I19) -> 172.40533 | J21: =AVERAGE(J5:J19) -> 0.0047060942 | Q21: =AVERAGE(Q5:Q19) -> 172.40533 | R21: =AVERAGE(R5:R19) -> 23.333333 | S21: =AVERAGE(S5:S19) -> 561.46667 | T21: =AVERAGE(T5:T19) -> 172.40533 | U21: =AVERAGE(U5:U19) -> 0.0039481254 | AA21: =AVERAGE(AA5:AA19) -> 5.1337193 | AB21: =AVERAGE(AB5:AB19) -> 3.1327362 | AC21: =AVERAGE(AC5:AC19) -> 5.1337193 | AD21: =AVERAGE(AD5:AD19) -> 171.79189 | AE21: =AVERAGE(AE5:AE19) -> 0.0038300364 | AK21: =AVERAGE(AK5:AK19) -> 5.1337193 | AL21: =AVERAGE(AL5:AL19) -> 23.333333 | AM21: =AVERAGE(AM5:AM19) -> 5.1337193 | AN21: =AVERAGE(AN5:AN19) -> 171.78454 | AO21: =AVERAGE(AO5:AO19) -> 0.0040439292 | AU21: =AVERAGE(AU5:AU19) -> 172.40533 | AV21: =AVERAGE(AV5:AV19) -> 3.1327362 | AW21: =AVERAGE(AW5:AW19) -> 172.40533 | AX21: =AVERAGE(AX5:AX19) -> 0.004200077
G24: ВЫВОД ИТОГОВ | Q24: ВЫВОД ИТОГОВ | AA24: ВЫВОД ИТОГОВ | AK24: ВЫВОД ИТОГОВ | AU24: ВЫВОД ИТОГОВ
G26: Регрессионная статистика | Q26: Регрессионная статистика | AA26: Регрессионная статистика | AK26: Регрессионная статистика | AU26: Регрессионная статистика
G27: Множественный R | H27: 0.85985651 | Q27: Множественный R | R27: 0.86643302 | AA27: Множественный R | AB27: 0.88844811 | AK27: Множественный R | AL27: 0.88130079 | AU27: Множественный R | AV27: 0.86617909
G28: R-квадрат | H28: 0.73935322 | Q28: R-квадрат | R28: 0.75070618 | AA28: R-квадрат | AB28: 0.78934005 | AK28: R-квадрат | AL28: 0.77669108 | AU28: R-квадрат | AV28: 0.75026621
G29: Нормированный R-квадрат | H29: 0.71930347 | Q29: Нормированный R-квадрат | R29: 0.70915721 | AA29: Нормированный R-квадрат | AB29: 0.77313543 | AK29: Нормированный R-квадрат | AL29: 0.75951347 | AU29: Нормированный R-квадрат | AV29: 0.73105592
G30: Стандартная ошибка | H30: 16.589381 | Q30: Стандартная ошибка | R30: 16.886546 | AA30: Стандартная ошибка | AB30: 0.089799451 | AK30: Стандартная ошибка | AL30: 0.092456133 | AU30: Стандартная ошибка | AV30: 16.238378
G31: Наблюдения | H31: 15 | Q31: Наблюдения | R31: 15 | AA31: Наблюдения | AB31: 15 | AK31: Наблюдения | AL31: 15 | AU31: Наблюдения | AV31: 15
G33: Дисперсионный анализ | Q33: Дисперсионный анализ | AA33: Дисперсионный анализ | AK33: Дисперсионный анализ | AU33: Дисперсионный анализ
H34: df | I34: SS | J34: MS | K34: F | L34: Значимость F | R34: df | S34: SS | T34: MS | U34: F | V34: Значимость F | AB34: df | AC34: SS | AD34: MS | AE34: F | AF34: Значимость F | AL34: df | AM34: SS | AN34: MS | AO34: F | AP34: Значимость F | AV34: df | AW34: SS | AX34: MS | AY34: F | AZ34: Значимость F
G35: Регрессия | H35: 1 | I35: 10148.535 | J35: 10148.535 | K35: 36.875928 | L35: 3.9519017e-05 | Q35: Регрессия | R35: 2 | S35: 10304.368 | T35: 5152.184 | U35: 18.067985 | V35: 0.00024003196 | AA35: Регрессия | AB35: 1 | AC35: 0.39280125 | AD35: 0.39280125 | AE35: 48.710827 | AF35: 9.6344177e-06 | AK35: Регрессия | AL35: 1 | AM35: 0.38650672 | AN35: 0.38650672 | AO35: 45.215318 | AP35: 1.4170513e-05 | AU35: Регрессия | AV35: 1 | AW35: 10298.329 | AX35: 10298.329 | AY35: 39.055431 | AZ35: 2.9744495e-05
G36: Остаток | H36: 13 | I36: 3577.6984 | J36: 275.20757 | Q36: Остаток | R36: 12 | S36: 3421.865 | T36: 285.15542 | AA36: Остаток | AB36: 13 | AC36: 0.10483124 | AD36: 0.0080639414 | AK36: Остаток | AL36: 13 | AM36: 0.11112578 | AN36: 0.0085481366 | AU36: Остаток | AV36: 13 | AW36: 3427.9042 | AX36: 263.68494
G37: Итого | H37: 14 | I37: 13726.233 | Q37: Итого | R37: 14 | S37: 13726.233 | AA37: Итого | AB37: 14 | AC37: 0.49763249 | AK37: Итого | AL37: 14 | AM37: 0.49763249 | AU37: Итого | AV37: 14 | AW37: 13726.233
H39: Коэффициенты | I39: Стандартная ошибка | J39: t-статистика | K39: P-Значение | L39: Нижние 95% | M39: Верхние 95% | N39: Нижние 95,0% | O39: Верхние 95,0% | R39: Коэффициенты | S39: Стандартная ошибка | T39: t-статистика | U39: P-Значение | V39: Нижние 95% | W39: Верхние 95% | X39: Нижние 95,0% | Y39: Верхние 95,0% | AB39: Коэффициенты | AC39: Стандартная ошибка | AD39: t-статистика | AE39: P-Значение | AF39: Нижние 95% | AG39: Верхние 95% | AH39: Нижние 95,0% | AI39: Верхние 95,0% | AL39: Коэффициенты | AM39: Стандартная ошибка | AN39: t-статистика | AO39: P-Значение | AP39: Нижние 95% | AQ39: Верхние 95% | AR39: Нижние 95,0% | AS39: Верхние 95,0% | AV39: Коэффициенты | AW39: Стандартная ошибка | AX39: t-статистика | AY39: P-Значение | AZ39: Нижние 95% | BA39: Верхние 95% | BB39: Нижние 95,0% | BC39: Верхние 95,0%
G40: Y-пересечение | H40: 300.56669 | I40: 21.53529 | J40: 13.956937 | K40: 3.347558e-09 | L40: 254.04252 | M40: 347.09086 | N40: 254.04252 | O40: 347.09086 | Q40: Y-пересечение | R40: -10.992429 | S40: 141.74646 | T40: -0.077549937 | U40: 0.93946413 | V40: -319.83142 | W40: 297.84657 | X40: -319.83142 | Y40: 297.84657 | AA40: Y-пересечение | AB40: 2.4619975 | AC40: 0.3835073 | AD40: 6.4196888 | AE40: 2.2719577e-05 | AF40: 1.6334804 | AG40: 3.2905147 | AH40: 1.6334804 | AI40: 3.2905147 | AK40: Y-пересечение | AL40: 4.2258955 | AM40: 0.13710205 | AN40: 30.822992 | AO40: 1.5348813e-13 | AP40: 3.9297045 | AQ40: 4.5220865 | AR40: 3.9297045 | AS40: 4.5220865 | AU40: Y-пересечение | AV40: -260.19631 | AW40: 69.349386 | AX40: -3.7519628 | AY40: 0.0024184277 | AZ40: -410.01655 | BA40: -110.37608 | BB40: -410.01655 | BC40: -110.37608
G41: z₂ = 1/x₂ | H41: -2884.8537 | I41: 475.0642 | J41: -6.0725553 | K41: 3.9519017e-05 | L41: -3911.1675 | M41: -1858.5398 | N41: -3911.1675 | O41: -1858.5398 | Q41: z₁ = x₂ | R41: 9.6281616 | S41: 13.011032 | T41: 0.73999983 | U41: 0.47352981 | V41: -18.720442 | W41: 37.976765 | X41: -18.720442 | Y41: 37.976765 | AA41: X = ln(x₂) | AB41: 0.85283967 | AC41: 0.12219534 | AD41: 6.9793142 | AE41: 9.6344177e-06 | AF41: 0.58885269 | AG41: 1.1168267 | AH41: 0.58885269 | AI41: 1.1168267 | AK41: x₂ | AL41: 0.038906733 | AM41: 0.0057860471 | AN41: 6.7242337 | AO41: 1.4170513e-05 | AP41: 0.026406738 | AQ41: 0.051406728 | AR41: 0.026406738 | AS41: 0.051406728 | AU41: z₂=ln(x₂) | AV41: 138.09067 | AW41: 22.096507 | AX41: 6.2494345 | AY41: 2.9744495e-05 | AZ41: 90.35407 | BA41: 185.82727 | BB41: 90.35407 | BC41: 185.82727
Q42: z₂ = x₂² | R42: -0.073484936 | S42: 0.29043686 | T42: -0.25301518 | U42: 0.80453884 | V42: -0.7062925 | W42: 0.55932263 | X42: -0.7062925 | Y42: 0.55932263
G45: ВЫВОД ОСТАТКА | AA45: ВЫВОД ОСТАТКА | AK45: ВЫВОД ОСТАТКА | AU45: ВЫВОД ОСТАТКА
Q46: ВЫВОД ОСТАТКА
G47: Наблюдение | H47: Предсказанное Розничный товарооброт (y) | I47: Остатки | Q47: Наблюдение | R47: Предсказанное Розничный товарооброт (y) | S47: Остатки | AA47: Наблюдение | AB47: Предсказанное Y = ln(y) | AC47: Остатки | AK47: Наблюдение | AL47: Предсказанное Y = ln(y) | AM47: Остатки | AU47: Наблюдение | AV47: Предсказанное y | AW47: Остатки
G48: 1 | H48: 108.24311 | I48: 10.316887 | Q48: 1 | R48: 116.89588 | S48: 1.6641152 | AA48: 1 | AB48: 4.7715302 | AC48: 0.0038889794 | AK48: 1 | AL48: 4.8094965 | AM48: -0.034077347 | AU48: 1 | AV48: 113.76015 | AW48: 4.7998466
G49: 2 | H49: 140.29704 | I49: -15.337042 | Q49: 2 | R49: 138.50536 | S49: -13.545361 | AA49: 2 | AB49: 4.9270212 | AC49: -0.099027552 | AK49: 2 | AL49: 4.9262167 | AM49: -0.098223022 | AU49: 2 | AV49: 138.93706 | AW49: -13.977059
G50: 3 | H50: 140.29704 | I50: -6.1370423 | Q50: 3 | R50: 138.50536 | S50: -4.345361 | AA50: 3 | AB50: 4.9270212 | AC50: -0.027988121 | AK50: 3 | AL50: 4.9262167 | AM50: -0.02718359 | AU50: 3 | AV50: 138.93706 | AW50: -4.7770594
G51: 4 | H51: 148.73229 | I51: 6.3077131 | Q51: 4 | R51: 145.41458 | S51: 9.6254201 | AA51: 4 | AB51: 4.9731319 | AC51: 0.070551238 | AK51: 4 | AL51: 4.9651234 | AM51: 0.078559707 | AU51: 4 | AV51: 146.40324 | AW51: 8.6367617
...

Sheet З-7. Множ. регрессия
A1: Диагностика мультиколлинеарности
A2: Коэффициент | B2: Значение | C2: Интепретация
A3: rx1x2 | B3: ='З-1. Данные'!R22/SQRT('З-1. Данные'!N22*'З-1. Данные'!O22) -> 0.63219504 | C3: Связь заметная, следовательно есть проблема интеркорреляции
A7: Отбор факторов в уравнение множественной регресии
A8: Предварительный анализ
A9: Коэффициент | B9: Значение | C9: Интепретация
A10: ryx1 | B10: ='З-1. Данные'!S22 / SQRT('З-1. Данные'!M22*'З-1. Данные'!N22) -> 0.7763193 | C10: Связь тесная. rx1x2 < ryx1 значит, имеет смысл включать x1 в регрессию
A11: ryx2 | B11: ='З-1. Данные'!T22 / SQRT('З-1. Данные'!M22*'З-1. Данные'!O22) -> 0.86566522 | C11: Связь тесная. rx1x2 < ryx2 значит, имеет смысл включать x1 в регрессию
A14: Точная оценка (частные коэффициенты корреляции)
A15: Коэффициент | B15: Значение | C15: Интепретация
A16: ryx1-x2 | B16: =(B10 - B11 * B3) / SQRT((1 - B11^2) * (1 - B3^2)) -> 0.5905062 | C16: В чистом виде связь заметная
A17: ryx2-x1 | B17: =(B11 - B10 * B3) / SQRT((1 - B10^2) * (1 - B3^2)) -> 0.7675783 | C17: В чистом виде связь также тесная
A19: Точная оценка (частные коэффициенты детерминации)
A20: Коэффициент | B20: Первый способ | C20: Второй способ | D20: Интепретация
A21: R²yx1-x2 | B21: =B16^2 -> 0.34869757 | C21: =('З-1. Данные'!Q22 - 'З-1. Данные'!V22) / 'З-1. Данные'!Q22 -> 0.34869757 | D21: В чистом виде объем промышленного производства на 34% объяняет вариацию розничного товарооборота
A22: R²yx2-x1 | B22: =B17^2 -> 0.58917644 | C22: =('З-1. Данные'!P22-'З-1. Данные'!V22) / 'З-1. Данные'!P22 -> 0.58917644 | D22: В чистом виде среднедушевой денежный доход на 58% объяняет вариацию розничного товарооборота
A26: Оценка значимости уравенния множественной регрессии
B27: df | C27: SS | D27: MS | E27: F_fact | F27: p_value | G27: Интерпретация
A28: Регрессия | B28: 2 | C28: 11485.675 | D28: 5742.8373 | E28: 30.757533 | F28: 1.8916002e-05 | G28: p_value < 0.05. Следовательно, уравнению множественной линейной регрессии значимо с вероятностью 95%
A29: Остаток | B29: 12 | C29: 2240.5584 | D29: 186.7132
A32: Оценка значимости коэф множественной регрессии
A33: t-критерий
B34: Значение | C34: se | D34: t_fact | E34: p_value | F34: Интерпретация
A35: b̂₁ | B35: 0.30286119 | C35: 0.11948679 | D35: 2.5346835 | E35: 0.026193005 | F35: p-value = 0.03 < 0.05. Следовательно, коэф. Регрессии b̂₁ статистически значим
A36: b̂₂ | B36: 4.5785142 | C36: 1.1036692 | D36: 4.1484479 | E36: 0.0013503188 | F36: p-value = 0.0014 < 0.05. Следовательно, коэф регрессии b̂₂ статистически значим
A38: Частный F-критерий
A39: Переменная | B39: SS(2)oст | C39: SS(1)oст | D39: F_част | E39: F_crit | F39: Интерпретация
A40: x1 | B40: ='З-1. Данные'!V22 -> 2240.5584 | C40: ='З-1. Данные'!Q22 -> 3440.1198 | D40: =((C40 -B40) / 1) / (B40 / (15 - 2 - 1)) -> 6.4246204 | E40: =_xlfn.F.INV.RT(0.05,1,15-2-1) -> 4.7472253 | F40: Для обеих переменных F_част > F_crit. Следовательно, включение обеих переменных значимо с вероятностью 95%
A41: x2 | B41: ='З-1. Данные'!V22 -> 2240.5584 | C41: ='З-1. Данные'!P22 -> 5453.8215 | D41: =((C41 -B41) / 1) / (B41 / (15 - 2 - 1)) -> 17.20962

Sheet З-8. Анализ случ. остатков
A1: Имеются следующие данные об уровне розничного товарооборота (млн. руб) | G1: Дано:
C2: объеме промышленного производства (млн. руб) | G2: Y - данные об розничном товарообороте
C3: среднедушевом денежном доходе (тыс. руб) | G3: X - данные об промышленном производстве
B5: 1. Анализ гомоскедастичности
B7: Данные | I7: Тест Гольфельда-Квандта | S7: Тест Спирмена | AC7: Тест Уайта: Ye = b0 + b11 * Z₁ + b12 * Z₂ + u | AP7: Тест Парка: ln(E²) = b0 + b1 * ln(X) + δ | AZ7: Тест Глейзера: |E| = b0 + b1 * Xk + δ
B8: Номер | C8: Розничный товарооброт (y) | D8: Объем промышленного производства (x₁) | E8: Среднедушевойденежный доход (x₂) | F8: Прогноз по степенной регрессии (ŷ) | G8: ln(ε) | I8: Номер | J8: Розничный товарооброт (y) | K8: Объем промышленного производства (x₁) | L8: Отсортированная (x₂) | M8: Y=ln(y) | N8: X=ln(x₂) | S8: Номер | T8: X = ln(x₂) | U8: E = ln(ε) | V8: rang(X) | W8: rang(E) | X8: d² | AC8: Номер | AD8: Розничный товарооброт (y) | AE8: Объем промышленного производства (x₁) | AF8: Отсортированная (x₂) | AG8: Y=ln(y) | AH8: X=ln(x₂) (линеаризация Z1=X) | AI8: X² (линеаризация Z2=X²) | AJ8: E = ln(ε) | AK8: E² (линеаризация Ye = E²) | AP8: Номер | AQ8: X=ln(x₂) | AR8: E = ln(ε) | AS8: ln(X) | AT8: E² | AU8: ln(E²) | AZ8: Номер | BA8: X=ln(x₂) | BB8: E = ln(ε) | BC8: Xk при k = -1 | BD8: Xk при k = -0,5 | BE8: Xk при k = 0,5 | BF8: Xk при k = 1 | BG8: |E|
B9: 1 | C9: 118.56 | D9: 247 | E9: 15 | F9: ='З-6. Анализ нелинейных функций'!AD5 -> 118.09982 | G9: ='З-6. Анализ нелинейных функций'!AC48 -> 0.0038889794 | I9: 1 | J9: 118.56 | K9: 247 | L9: 15 | M9: =LN(J9) -> 4.7754192 | N9: =LN(L9) -> 2.7080502 | S9: 1 | T9: =LN($E9) -> 2.7080502 | U9: =G9 -> 0.0038889794 | V9: =_xlfn.RANK.AVG(T9,$T$9:$T$23,1) -> 1 | W9: =_xlfn.RANK.AVG(U9,$U$9:$U$23,1) -> 8 | X9: =(V9-W9)^2 -> 49 | AC9: 1 | AD9: 118.56 | AE9: 247 | AF9: 15 | AG9: =LN(AD9) -> 4.7754192 | AH9: =LN(AF9) -> 2.7080502 | AI9: =AH9^2 -> 7.3335359 | AJ9: =G9 -> 0.0038889794 | AK9: =AJ9^2 -> 1.5124161e-05 | AP9: 1 | AQ9: =LN($E9) -> 2.7080502 | AR9: =G9 -> 0.0038889794 | AS9: =LN(AQ9) -> 0.99622889 | AT9: =AR9^2 -> 1.5124161e-05 | AU9: =LN(AT9) -> -11.099217 | AZ9: 1 | BA9: =LN($E9) -> 2.7080502 | BB9: =G9 -> 0.0038889794 | BC9: =BA9^(-1) -> 0.36926937 | BD9: =BA9^(-0.5) -> 0.60767538 | BE9: =BA9^(0.5) -> 1.6456154 | BF9: =BA9^(1) -> 2.7080502 | BG9: =ABS(BB9) -> 0.0038889794
B10: 2 | C10: 124.96 | D10: 284 | E10: 18 | F10: ='З-6. Анализ нелинейных функций'!AD6 -> 137.96793 | G10: ='З-6. Анализ нелинейных функций'!AC49 -> -0.099027552 | I10: 2 | J10: 124.96 | K10: 284 | L10: 18 | M10: =LN(J10) -> 4.8279937 | N10: =LN(L10) -> 2.8903718 | S10: 2 | T10: =LN($E10) -> 2.8903718 | U10: =G10 -> -0.099027552 | V10: =_xlfn.RANK.AVG(T10,$T$9:$T$23,1) -> 2.5 | W10: =_xlfn.RANK.AVG(U10,$U$9:$U$23,1) -> 2 | X10: =(V10-W10)^2 -> 0.25 | AC10: 2 | AD10: 124.96 | AE10: 284 | AF10: 18 | AG10: =LN(AD10) -> 4.8279937 | AH10: =LN(AF10) -> 2.8903718 | AI10: =AH10^2 -> 8.3542489 | AJ10: =G10 -> -0.099027552 | AK10: =AJ10^2 -> 0.0098064561 | AP10: 2 | AQ10: =LN($E10) -> 2.8903718 | AR10: =G10 -> -0.099027552 | AS10: =LN(AQ10) -> 1.0613851 | AT10: =AR10^2 -> 0.0098064561 | AU10: =LN(AT10) -> -4.6247143 | AZ10: 2 | BA10: =LN($E10) -> 2.8903718 | BB10: =G10 -> -0.099027552 | BC10: =BA10^(-1) -> 0.34597626 | BD10: =BA10^(-0.5) -> 0.58819746 | BE10: =BA10^(0.5) -> 1.7001093 | BF10: =BA10^(1) -> 2.8903718 | BG10: =ABS(BB10) -> 0.099027552
B11: 3 | C11: 134.16 | D11: 258 | E11: 18 | F11: ='З-6. Анализ нелинейных функций'!AD7 -> 137.96793 | G11: ='З-6. Анализ нелинейных функций'!AC50 -> -0.027988121 | I11: 3 | J11: 134.16 | K11: 258 | L11: 18 | M11: =LN(J11) -> 4.8990331 | N11: =LN(L11) -> 2.8903718 | S11: 3 | T11: =LN($E11) -> 2.8903718 | U11: =G11 -> -0.027988121 | V11: =_xlfn.RANK.AVG(T11,$T$9:$T$23,1) -> 2.5 | W11: =_xlfn.RANK.AVG(U11,$U$9:$U$23,1) -> 4 | X11: =(V11-W11)^2 -> 2.25 | AC11: 3 | AD11: 134.16 | AE11: 258 | AF11: 18 | AG11: =LN(AD11) -> 4.8990331 | AH11: =LN(AF11) -> 2.8903718 | AI11: =AH11^2 -> 8.3542489 | AJ11: =G11 -> -0.027988121 | AK11: =AJ11^2 -> 0.00078333492 | AP11: 3 | AQ11: =LN($E11) -> 2.8903718 | AR11: =G11 -> -0.027988121 | AS11: =LN(AQ11) -> 1.0613851 | AT11: =AR11^2 -> 0.00078333492 | AU11: =LN(AT11) -> -7.1519502 | AZ11: 3 | BA11: =LN($E11) -> 2.8903718 | BB11: =G11 -> -0.027988121 | BC11: =BA11^(-1) -> 0.34597626 | BD11: =BA11^(-0.5) -> 0.58819746 | BE11: =BA11^(0.5) -> 1.7001093 | BF11: =BA11^(1) -> 2.8903718 | BG11: =ABS(BB11) -> 0.027988121
B12: 4 | C12: 155.04 | D12: 323 | E12: 19 | F12: ='З-6. Анализ нелинейных функций'!AD8 -> 144.47867 | G12: ='З-6. Анализ нелинейных функций'!AC51 -> 0.070551238 | I12: 4 | J12: 155.04 | K12: 323 | L12: 19 | M12: =LN(J12) -> 5.0436831 | N12: =LN(L12) -> 2.944439 | S12: 4 | T12: =LN($E12) -> 2.944439 | U12: =G12 -> 0.070551238 | V12: =_xlfn.RANK.AVG(T12,$T$9:$T$23,1) -> 4 | W12: =_xlfn.RANK.AVG(U12,$U$9:$U$23,1) -> 13 | X12: =(V12-W12)^2 -> 81 | AC12: 4 | AD12: 155.04 | AE12: 323 | AF12: 19 | AG12: =LN(AD12) -> 5.0436831 | AH12: =LN(AF12) -> 2.944439 | AI12: =AH12^2 -> 8.6697209 | AJ12: =G12 -> 0.070551238 | AK12: =AJ12^2 -> 0.0049774772 | AP12: 4 | AQ12: =LN($E12) -> 2.944439 | AR12: =G12 -> 0.070551238 | AS12: =LN(AQ12) -> 1.0799183 | AT12: =AR12^2 -> 0.0049774772 | AU12: =LN(AT12) -> -5.3028321 | AZ12: 4 | BA12: =LN($E12) -> 2.944439 | BB12: =G12 -> 0.070551238 | BC12: =BA12^(-1) -> 0.33962327 | BD12: =BA12^(-0.5) -> 0.58277206 | BE12: =BA12^(0.5) -> 1.7159368 | BF12: =BA12^(1) -> 2.944439 | BG12: =ABS(BB12) -> 0.070551238
B13: 5 | C13: 161.12 | D13: 304 | E13: 27 | F13: ='З-6. Анализ нелинейных функций'!AD9 -> 194.96459 | G13: ='З-6. Анализ нелинейных функций'!AC52 -> -0.19066854 | I13: 5 | J13: 165.13 | K13: 337 | L13: 22 | M13: =LN(J13) -> 5.106733 | N13: =LN(L13) -> 3.0910425 | S13: 5 | T13: =LN($E13) -> 3.2958369 | U13: =G13 -> -0.19066854 | V13: =_xlfn.RANK.AVG(T13,$T$9:$T$23,1) -> 11 | W13: =_xlfn.RANK.AVG(U13,$U$9:$U$23,1) -> 1 | X13: =(V13-W13)^2 -> 100 | AC13: 5 | AD13: 165.13 | AE13: 337 | AF13: 22 | AG13: =LN(AD13) -> 5.106733 | AH13: =LN(AF13) -> 3.0910425 | AI13: =AH13^2 -> 9.5545434 | AJ13: =G13 -> -0.19066854 | AK13: =AJ13^2 -> 0.036354492 | AP13: 5 | AQ13: =LN($E13) -> 3.2958369 | AR13: =G13 -> -0.19066854 | AS13: =LN(AQ13) -> 1.1926601 | AT13: =AR13^2 -> 0.036354492 | AU13: =LN(AT13) -> -3.3144375 | AZ13: 5 | BA13: =LN($E13) -> 3.2958369 | BB13: =G13 -> -0.19066854 | BC13: =BA13^(-1) -> 0.30341308 | BD13: =BA13^(-0.5) -> 0.55082944 | BE13: =BA13^(0.5) -> 1.815444 | BF13: =BA13^(1) -> 3.2958369 | BG13: =ABS(BB13) -> 0.19066854
B14: 6 | C14: 165.13 | D14: 337 | E14: 22 | F14: ='З-6. Анализ нелинейных функций'!AD10 -> 163.72058 | G14: ='З-6. Анализ нелинейных функций'!AC53 -> 0.0085718742 | I14: 6 | J14: 190.62 | K14: 353 | L14: 22 | M14: =LN(J14) -> 5.2502819 | N14: =LN(L14) -> 3.0910425 | S14: 6 | T14: =LN($E14) -> 3.0910425 | U14: =G14 -> 0.0085718742 | V14: =_xlfn.RANK.AVG(T14,$T$9:$T$23,1) -> 5.5 | W14: =_xlfn.RANK.AVG(U14,$U$9:$U$23,1) -> 9 | X14: =(V14-W14)^2 -> 12.25 | AC14: 6 | AD14: 190.62 | AE14: 353 | AF14: 22 | AG14: =LN(AD14) -> 5.2502819 | AH14: =LN(AF14) -> 3.0910425 | AI14: =AH14^2 -> 9.5545434 | AJ14: =G14 -> 0.0085718742 | AK14: =AJ14^2 -> 7.3477027e-05 | AP14: 6 | AQ14: =LN($E14) -> 3.0910425 | AR14: =G14 -> 0.0085718742 | AS14: =LN(AQ14) -> 1.1285084 | AT14: =AR14^2 -> 7.3477027e-05 | AU14: =LN(AT14) -> -9.5185378 | AZ14: 6 | BA14: =LN($E14) -> 3.0910425 | BB14: =G14 -> 0.0085718742 | BC14: =BA14^(-1) -> 0.32351545 | BD14: =BA14^(-0.5) -> 0.56878419 | BE14: =BA14^(0.5) -> 1.7581361 | BF14: =BA14^(1) -> 3.0910425 | BG14: =ABS(BB14) -> 0.0085718742
B15: 7 | C15: 170 | D15: 340 | E15: 23 | F15: ='З-6. Анализ нелинейных функций'!AD11 -> 170.04641 | G15: ='З-6. Анализ нелинейных функций'!AC54 -> -0.00027295776 | I15: 7 | J15: 170 | K15: 340 | L15: 23 | M15: =LN(J15) -> 5.1357984 | N15: =LN(L15) -> 3.1354942 | S15: 7 | T15: =LN($E15) -> 3.1354942 | U15: =G15 -> -0.00027295776 | V15: =_xlfn.RANK.AVG(T15,$T$9:$T$23,1) -> 7 | W15: =_xlfn.RANK.AVG(U15,$U$9:$U$23,1) -> 7 | X15: =(V15-W15)^2 -> 0 | AC15: 7 | AD15: 170 | AE15: 340 | AF15: 23 | AG15: =LN(AD15) -> 5.1357984 | AH15: =LN(AF15) -> 3.1354942 | AI15: =AH15^2 -> 9.831324 | AJ15: =G15 -> -0.00027295776 | AK15: =AJ15^2 -> 7.450594e-08 | AP15: 7 | AQ15: =LN($E15) -> 3.1354942 | AR15: =G15 -> -0.00027295776 | AS15: =LN(AQ15) -> 1.1427868 | AT15: =AR15^2 -> 7.450594e-08 | AU15: =LN(AT15) -> -16.412387 | AZ15: 7 | BA15: =LN($E15) -> 3.1354942 | BB15: =G15 -> -0.00027295776 | BC15: =BA15^(-1) -> 0.31892899 | BD15: =BA15^(-0.5) -> 0.56473798 | BE15: =BA15^(0.5) -> 1.7707327 | BF15: =BA15^(1) -> 3.1354942 | BG15: =ABS(BB15) -> 0.00027295776
B16: 8 | C16: 174.42 | D16: 306 | E16: 24 | F16: ='З-6. Анализ нелинейных функций'!AD12 -> 176.33188 | G16: ='З-6. Анализ нелинейных функций'!AC55 -> -0.010901739 | I16: 8 | J16: 174.42 | K16: 306 | L16: 24 | M16: =LN(J16) -> 5.1614662 | N16: =LN(L16) -> 3.1780538 | S16: 8 | T16: =LN($E16) -> 3.1780538 | U16: =G16 -> -0.010901739 | V16: =_xlfn.RANK.AVG(T16,$T$9:$T$23,1) -> 8.5 | W16: =_xlfn.RANK.AVG(U16,$U$9:$U$23,1) -> 5 | X16: =(V16-W16)^2 -> 12.25 | AC16: 8 | AD16: 174.42 | AE16: 306 | AF16: 24 | AG16: =LN(AD16) -> 5.1614662 | AH16: =LN(AF16) -> 3.1780538 | AI16: =AH16^2 -> 10.100026 | AJ16: =G16 -> -0.010901739 | AK16: =AJ16^2 -> 0.0001188479 | AP16: 8 | AQ16: =LN($E16) -> 3.1780538 | AR16: =G16 -> -0.010901739 | AS16: =LN(AQ16) -> 1.156269 | AT16: =AR16^2 -> 0.0001188479 | AU16: =LN(AT16) -> -9.037666 | AZ16: 8 | BA16: =LN($E16) -> 3.1780538 | BB16: =G16 -> -0.010901739 | BC16: =BA16^(-1) -> 0.31465798 | BD16: =BA16^(-0.5) -> 0.56094383 | BE16: =BA16^(0.5) -> 1.7827097 | BF16: =BA16^(1) -> 3.1780538 | BG16: =ABS(BB16) -> 0.010901739
B17: 9 | C17: 175.45 | D17: 290 | E17: 24 | F17: ='З-6. Анализ нелинейных функций'!AD13 -> 176.33188 | G17: ='З-6. Анализ нелинейных функций'!AC56 -> -0.0050138203 | I17: 9 | J17: 175.45 | K17: 290 | L17: 24 | M17: =LN(J17) -> 5.1673541 | N17: =LN(L17) -> 3.1780538 | S17: 9 | T17: =LN($E17) -> 3.1780538 | U17: =G17 -> -0.0050138203 | V17: =_xlfn.RANK.AVG(T17,$T$9:$T$23,1) -> 8.5 | W17: =_xlfn.RANK.AVG(U17,$U$9:$U$23,1) -> 6 | X17: =(V17-W17)^2 -> 6.25 | AC17: 9 | AD17: 175.45 | AE17: 290 | AF17: 24 | AG17: =LN(AD17) -> 5.1673541 | AH17: =LN(AF17) -> 3.1780538 | AI17: =AH17^2 -> 10.100026 | AJ17: =G17 -> -0.0050138203 | AK17: =AJ17^2 -> 2.5138394e-05 | AP17: 9 | AQ17: =LN($E17) -> 3.1780538 | AR17: =G17 -> -0.0050138203 | AS17: =LN(AQ17) -> 1.156269 | AT17: =AR17^2 -> 2.5138394e-05 | AU17: =LN(AT17) -> -10.591114 | AZ17: 9 | BA17: =LN($E17) -> 3.1780538 | BB17: =G17 -> -0.0050138203 | BC17: =BA17^(-1) -> 0.31465798 | BD17: =BA17^(-0.5) -> 0.56094383 | BE17: =BA17^(0.5) -> 1.7827097 | BF17: =BA17^(1) -> 3.1780538 | BG17: =ABS(BB17) -> 0.0050138203
B18: 10 | C18: 177.48 | D18: 348 | E18: 27 | F18: ='З-6. Анализ нелинейных функций'!AD14 -> 194.96459 | G18: ='З-6. Анализ нелинейных функций'!AC57 -> -0.093960041 | I18: 10 | J18: 161.12 | K18: 304 | L18: 27 | M18: =LN(J18) -> 5.0821494 | N18: =LN(L18) -> 3.2958369 | S18: 10 | T18: =LN($E18) -> 3.2958369 | U18: =G18 -> -0.093960041 | V18: =_xlfn.RANK.AVG(T18,$T$9:$T$23,1) -> 11 | W18: =_xlfn.RANK.AVG(U18,$U$9:$U$23,1) -> 3 | X18: =(V18-W18)^2 -> 64 | AC18: 10 | AD18: 161.12 | AE18: 304 | AF18: 27 | AG18: =LN(AD18) -> 5.0821494 | AH18: =LN(AF18) -> 3.2958369 | AI18: =AH18^2 -> 10.862541 | AJ18: =G18 -> -0.093960041 | AK18: =AJ18^2 -> 0.0088284893 | AP18: 10 | AQ18: =LN($E18) -> 3.2958369 | AR18: =G18 -> -0.093960041 | AS18: =LN(AQ18) -> 1.1926601 | AT18: =AR18^2 -> 0.0088284893 | AU18: =LN(AT18) -> -4.7297714 | AZ18: 10 | BA18: =LN($E18) -> 3.2958369 | BB18: =G18 -> -0.093960041 | BC18: =BA18^(-1) -> 0.30341308 | BD18: =BA18^(-0.5) -> 0.55082944 | BE18: =BA18^(0.5) -> 1.815444 | BF18: =BA18^(1) -> 3.2958369 | BG18: =ABS(BB18) -> 0.093960041
B19: 11 | C19: 190.62 | D19: 353 | E19: 22 | F19: ='З-6. Анализ нелинейных функций'!AD15 -> 163.72058 | G19: ='З-6. Анализ нелинейных функций'!AC58 -> 0.15212075 | I19: 11 | J19: 177.48 | K19: 348 | L19: 27 | M19: =LN(J19) -> 5.1788579 | N19: =LN(L19) -> 3.2958369 | S19: 11 | T19: =LN($E19) -> 3.0910425 | U19: =G19 -> 0.15212075 | V19: =_xlfn.RANK.AVG(T19,$T$9:$T$23,1) -> 5.5 | W19: =_xlfn.RANK.AVG(U19,$U$9:$U$23,1) -> 15 | X19: =(V19-W19)^2 -> 90.25 | AC19: 11 | AD19: 177.48 | AE19: 348 | AF19: 27 | AG19: =LN(AD19) -> 5.1788579 | AH19: =LN(AF19) -> 3.2958369 | AI19: =AH19^2 -> 10.862541 | AJ19: =G19 -> 0.15212075 | AK19: =AJ19^2 -> 0.023140722 | AP19: 11 | AQ19: =LN($E19) -> 3.0910425 | AR19: =G19 -> 0.15212075 | AS19: =LN(AQ19) -> 1.1285084 | AT19: =AR19^2 -> 0.023140722 | AU19: =LN(AT19) -> -3.7661613 | AZ19: 11 | BA19: =LN($E19) -> 3.0910425 | BB19: =G19 -> 0.15212075 | BC19: =BA19^(-1) -> 0.32351545 | BD19: =BA19^(-0.5) -> 0.56878419 | BE19: =BA19^(0.5) -> 1.7581361 | BF19: =BA19^(1) -> 3.0910425 | BG19: =ABS(BB19) -> 0.15212075
